Workbook

Sheet Principal_detalhado (2)
A2: Item | B2: Valor Unitário | C2: nº períodos | D2: Qtde | E2: Total
A3: AR Inmo Air3 | B3: 7500 | C3: 1 | D3: 1 | E3: =tab_principal9[[#This Row],[Valor Unitário]]*tab_principal9[[#This Row],[nº períodos]]*tab_principal9[[#This Row],[Qtde]] -> 7500
A4: Bicicleta elétrica Fisioterapia | B4: 3000 | C4: 1 | D4: 1 | E4: =tab_principal9[[#This Row],[Valor Unitário]]*tab_principal9[[#This Row],[nº períodos]]*tab_principal9[[#This Row],[Qtde]] -> 3000
A5: Bolsa de Coordenação - A | B5: 6900 | C5: 18 | D5: 1 | E5: =tab_principal9[[#This Row],[Valor Unitário]]*tab_principal9[[#This Row],[nº períodos]]*tab_principal9[[#This Row],[Qtde]] -> 124200
A6: Bolsa de Coordenação - D | B6: 6900 | C6: 18 | D6: 1 | E6: =tab_principal9[[#This Row],[Valor Unitário]]*tab_principal9[[#This Row],[nº períodos]]*tab_principal9[[#This Row],[Qtde]] -> 124200
A7: Bolsa de Coordenação - H | B7: 6900 | C7: 18 | D7: 1 | E7: =tab_principal9[[#This Row],[Valor Unitário]]*tab_principal9[[#This Row],[nº períodos]]*tab_principal9[[#This Row],[Qtde]] -> 124200
A8: Bolsa de Coordenação - R | B8: 6900 | C8: 18 | D8: 1 | E8: =tab_principal9[[#This Row],[Valor Unitário]]*tab_principal9[[#This Row],[nº períodos]]*tab_principal9[[#This Row],[Qtde]] -> 124200
A9: Bolsa para Doutorando - A | B9: 4000 | C9: 18 | D9: 1 | E9: =tab_principal9[[#This Row],[Valor Unitário]]*tab_principal9[[#This Row],[nº períodos]]*tab_principal9[[#This Row],[Qtde]] -> 72000
A10: Computadores | B10: 13590.5 | C10: 1 | D10: 0 | E10: =tab_principal9[[#This Row],[Valor Unitário]]*tab_principal9[[#This Row],[nº períodos]]*tab_principal9[[#This Row],[Qtde]] -> 0
A11: Bolsa para Doutorando - D | B11: 4000 | C11: 18 | D11: 1 | E11: =tab_principal9[[#This Row],[Valor Unitário]]*tab_principal9[[#This Row],[nº períodos]]*tab_principal9[[#This Row],[Qtde]] -> 72000
A12: Bolsas de Mestrado | B12: 3000 | C12: 18 | D12: 0 | E12: =tab_principal9[[#This Row],[Valor Unitário]]*tab_principal9[[#This Row],[nº períodos]]*tab_principal9[[#This Row],[Qtde]] -> 0
A13: Bolsa para Doutorando - R | B13: 4000 | C13: 18 | D13: 1 | E13: =tab_principal9[[#This Row],[Valor Unitário]]*tab_principal9[[#This Row],[nº períodos]]*tab_principal9[[#This Row],[Qtde]] -> 72000
A14: Bolsas de Graduação | B14: 1500 | C14: 18 | D14: 2 | E14: =tab_principal9[[#This Row],[Valor Unitário]]*tab_principal9[[#This Row],[nº períodos]]*tab_principal9[[#This Row],[Qtde]] -> 54000
... A17: Bolsas de Mestrado - H | B17: 3000 | C17: 18 | D17: 1 | E17: =tab_principal9[[#This Row],[Valor Unitário]]*tab_principal9[[#This Row],[nº períodos]]*tab_principal9[[#This Row],[Qtde]] -> 54000
A18: Software de Gerenciamento de Projeto (Trello Premium) | B18: =5*12*aux!$C$20 -> 330 | C18: 2 | D18: 0 | E18: =tab_principal9[[#This Row],[Valor Unitário]]*tab_principal9[[#This Row],[nº períodos]]*tab_principal9[[#This Row],[Qtde]] -> 0
A19: Software de sincronização de arquivos (Dropbox Plus) | B19: =10*aux!$C$20 -> 55 | C19: 18 | D19: 0 | E19: =tab_principal9[[#This Row],[Valor Unitário]]*tab_principal9[[#This Row],[nº períodos]]*tab_principal9[[#This Row],[Qtde]] -> 0
A20: Software de versionamento (GitHub Pro Team) | B20: 22 | C20: 18 | D20: 0 | E20: =tab_principal9[[#This Row],[Valor Unitário]]*tab_principal9[[#This Row],[nº períodos]]*tab_principal9[[#This Row],[Qtde]] -> 0
A21: Taxa Publicação Congresso ou Periódico | B21: 15000 | C21: 1 | D21: 0 | E21: =tab_principal9[[#This Row],[Valor Unitário]]*tab_principal9[[#This Row],[nº períodos]]*tab_principal9[[#This Row],[Qtde]] -> 0
A22: Todoist Business | B22: 396 | C22: 2 | D22: 0 | E22: =tab_principal9[[#This Row],[Valor Unitário]]*tab_principal9[[#This Row],[nº períodos]]*tab_principal9[[#This Row],[Qtde]] -> 0
A23: Bolsas de Pós-Doutorado | B23: 7200 | C23: 18 | D23: 1 | E23: =tab_principal9[[#This Row],[Valor Unitário]]*tab_principal9[[#This Row],[nº períodos]]*tab_principal9[[#This Row],[Qtde]] -> 129600
A24: Bolsas para Graduando | B24: 1100 | C24: 18 | D24: 2 | E24: =tab_principal9[[#This Row],[Valor Unitário]]*tab_principal9[[#This Row],[nº períodos]]*tab_principal9[[#This Row],[Qtde]] -> 39600
A25: Computador para Coordenador - H | B25: 18000 | C25: 1 | D25: 1 | E25: =tab_principal9[[#This Row],[Valor Unitário]]*tab_principal9[[#This Row],[nº períodos]]*tab_principal9[[#This Row],[Qtde]] -> 18000
A26: Computadores para Alunos | B26: 15000 | C26: 1 | D26: 4 | E26: =tab_principal9[[#This Row],[Valor Unitário]]*tab_principal9[[#This Row],[nº períodos]]*tab_principal9[[#This Row],[Qtde]] -> 60000
A27: Diária Internacional - A | B27: 2035 | C27: 1 | D27: 0 | E27: =tab_principal9[[#This Row],[Valor Unitário]]*tab_principal9[[#This Row],[nº períodos]]*tab_principal9[[#This Row],[Qtde]] -> 0
A28: Diária Internacional - D | B28: 2035 | C28: 1 | D28: 0 | E28: =tab_principal9[[#This Row],[Valor Unitário]]*tab_principal9[[#This Row],[nº períodos]]*tab_principal9[[#This Row],[Qtde]] -> 0
A29: Diária Internacional - R | B29: 2035 | C29: 1 | D29: 0 | E29: =tab_principal9[[#This Row],[Valor Unitário]]*tab_principal9[[#This Row],[nº períodos]]*tab_principal9[[#This Row],[Qtde]] -> 0
A30: Diária Nacional - - Vinda Anselmo e aluno | B30: 350 | C30: 1 | D30: 14 | E30: =tab_principal9[[#This Row],[Valor Unitário]]*tab_principal9[[#This Row],[nº períodos]]*tab_principal9[[#This Row],[Qtde]] -> 4900
A31: Diária Nacional - Workshop | B31: 350 | C31: 1 | D31: 4 | E31: =tab_principal9[[#This Row],[Valor Unitário]]*tab_principal9[[#This Row],[nº períodos]]*tab_principal9[[#This Row],[Qtde]] -> 1400
... A37: Exoesqueleto | B37: 1000000 | C37: 1 | D37: 1 | E37: =tab_principal9[[#This Row],[Valor Unitário]]*tab_principal9[[#This Row],[nº períodos]]*tab_principal9[[#This Row],[Qtde]] -> 1000000
A38: FINATEC: despesas operacionais e administrativas para gestão do projeto | B38: =0.15*Consolidado!C3 -> 436800 | C38: 1 | D38: 1 | E38: =tab_principal9[[#This Row],[Valor Unitário]]*tab_principal9[[#This Row],[nº períodos]]*tab_principal9[[#This Row],[Qtde]] -> 436800
A39: IMUs YEI PrioVR | B39: 17900 | C39: 1 | D39: 1 | E39: =tab_principal9[[#This Row],[Valor Unitário]]*tab_principal9[[#This Row],[nº períodos]]*tab_principal9[[#This Row],[Qtde]] -> 17900
A40: Manutenção preventiva/corretiva do parque de equipamentos | B40: 100000 | C40: 1 | D40: 1 | E40: =tab_principal9[[#This Row],[Valor Unitário]]*tab_principal9[[#This Row],[nº períodos]]*tab_principal9[[#This Row],[Qtde]] -> 100000
A41: Material para prototipagem eletromecânico | B41: 0 | C41: 1 | D41: 1 | E41: =tab_principal9[[#This Row],[Valor Unitário]]*tab_principal9[[#This Row],[nº períodos]]*tab_principal9[[#This Row],[Qtde]] -> 0
A42: Material para prototipagem eletromecânico | B42: 0 | C42: 1 | D42: 1 | E42: =tab_principal9[[#This Row],[Valor Unitário]]*tab_principal9[[#This Row],[nº períodos]]*tab_principal9[[#This Row],[Qtde]] -> 0
A43: Passagem internacional ida e votla - A | B43: 10000 | C43: 1 | D43: 0 | E43: =tab_principal9[[#This Row],[Valor Unitário]]*tab_principal9[[#This Row],[nº períodos]]*tab_principal9[[#This Row],[Qtde]] -> 0
A44: Passagem internacional ida e votla - D | B44: 10000 | C44: 1 | D44: 0 | E44: =tab_principal9[[#This Row],[Valor Unitário]]*tab_principal9[[#This Row],[nº períodos]]*tab_principal9[[#This Row],[Qtde]] -> 0
A45: Computadores | B45: 13590.5 | C45: 1 | D45: 0 | E45: =tab_principal9[[#This Row],[Valor Unitário]]*tab_principal9[[#This Row],[nº períodos]]*tab_principal9[[#This Row],[Qtde]] -> 0
A46: Passagem internacional ida e votla - R | B46: 10000 | C46: 1 | D46: 0 | E46: =tab_principal9[[#This Row],[Valor Unitário]]*tab_principal9[[#This Row],[nº períodos]]*tab_principal9[[#This Row],[Qtde]] -> 0
A47: Bolsa para Doutorando - H | B47: 4000 | C47: 18 | D47: 0 | E47: =tab_principal9[[#This Row],[Valor Unitário]]*tab_principal9[[#This Row],[nº períodos]]*tab_principal9[[#This Row],[Qtde]] -> 0
A48: Passagem nacional ida e volta - A | B48: 4000 | C48: 1 | D48: 0 | E48: =tab_principal9[[#This Row],[Valor Unitário]]*tab_principal9[[#This Row],[nº períodos]]*tab_principal9[[#This Row],[Qtde]] -> 0
...

Sheet Principal_detalhado
A2: Item | B2: Valor Unitário | C2: nº períodos | D2: Qtde | E2: Total | F2: Categoria | G2: Cota de quem | H2: Tipo de Verba
A3: AR Inmo Air3 | B3: 7500 | C3: 1 | D3: 1 | E3: =tab_principal[[#This Row],[Valor Unitário]]*tab_principal[[#This Row],[nº períodos]]*tab_principal[[#This Row],[Qtde]] -> 7500 | F3: Permanente | G3: Comum | H3: Capital
A4: Bicicleta elétrica Fisioterapia | B4: 3000 | C4: 1 | D4: 1 | E4: =tab_principal[[#This Row],[Valor Unitário]]*tab_principal[[#This Row],[nº períodos]]*tab_principal[[#This Row],[Qtde]] -> 3000 | F4: Permanente | G4: Comum | H4: Capital
A5: Bolsa de Coordenação - A | B5: 6900 | C5: 18 | D5: 1 | E5: =tab_principal[[#This Row],[Valor Unitário]]*tab_principal[[#This Row],[nº períodos]]*tab_principal[[#This Row],[Qtde]] -> 124200 | F5: Bolsa | G5: Anselmo | H5: Custeio
A6: Bolsa de Coordenação - D | B6: 6900 | C6: 18 | D6: 1 | E6: =tab_principal[[#This Row],[Valor Unitário]]*tab_principal[[#This Row],[nº períodos]]*tab_principal[[#This Row],[Qtde]] -> 124200 | F6: Bolsa | G6: Durigan | H6: Custeio
A7: Bolsa de Coordenação - H | B7: 6900 | C7: 18 | D7: 1 | E7: =tab_principal[[#This Row],[Valor Unitário]]*tab_principal[[#This Row],[nº períodos]]*tab_principal[[#This Row],[Qtde]] -> 124200 | F7: Bolsa | G7: Henrique | H7: Custeio
A8: Bolsa de Coordenação - R | B8: 6900 | C8: 18 | D8: 1 | E8: =tab_principal[[#This Row],[Valor Unitário]]*tab_principal[[#This Row],[nº períodos]]*tab_principal[[#This Row],[Qtde]] -> 124200 | F8: Bolsa | G8: Roberto | H8: Custeio
A9: Bolsa para Doutorando - A | B9: 4000 | C9: 18 | D9: 1 | E9: =tab_principal[[#This Row],[Valor Unitário]]*tab_principal[[#This Row],[nº períodos]]*tab_principal[[#This Row],[Qtde]] -> 72000 | F9: Bolsa | G9: Anselmo | H9: Custeio
A10: Computadores | B10: 13590.5 | C10: 1 | D10: 0 | E10: =tab_principal[[#This Row],[Valor Unitário]]*tab_principal[[#This Row],[nº períodos]]*tab_principal[[#This Row],[Qtde]] -> 0 | F10: Permanente | G10: Anselmo | H10: Custeio
A11: Bolsa para Doutorando - D | B11: 4000 | C11: 18 | D11: 1 | E11: =tab_principal[[#This Row],[Valor Unitário]]*tab_principal[[#This Row],[nº períodos]]*tab_principal[[#This Row],[Qtde]] -> 72000 | F11: Bolsa | G11: Durigan | H11: Custeio
A12: Bolsas de Mestrado | B12: 3000 | C12: 18 | D12: 0 | E12: =tab_principal[[#This Row],[Valor Unitário]]*tab_principal[[#This Row],[nº períodos]]*tab_principal[[#This Row],[Qtde]] -> 0 | F12: Bolsa | G12: Comum | H12: Custeio
A13: Bolsa para Doutorando - R | B13: 4000 | C13: 18 | D13: 1 | E13: =tab_principal[[#This Row],[Valor Unitário]]*tab_principal[[#This Row],[nº períodos]]*tab_principal[[#This Row],[Qtde]] -> 72000 | F13: Bolsa | G13: Roberto | H13: Custeio
A14: Bolsas de Graduação | B14: 1500 | C14: 18 | D14: 2 | E14: =tab_principal[[#This Row],[Valor Unitário]]*tab_principal[[#This Row],[nº períodos]]*tab_principal[[#This Row],[Qtde]] -> 54000 | F14: Bolsa | G14: Comum | H14: Custeio
... A17: Bolsas de Mestrado - H | B17: 3000 | C17: 18 | D17: 1 | E17: =tab_principal[[#This Row],[Valor Unitário]]*tab_principal[[#This Row],[nº períodos]]*tab_principal[[#This Row],[Qtde]] -> 54000 | F17: Bolsa | G17: Henrique | H17: Custeio
A18: Software de Gerenciamento de Projeto (Trello Premium) | B18: =5*12*aux!$C$20 -> 330 | C18: 2 | D18: 0 | E18: =tab_principal[[#This Row],[Valor Unitário]]*tab_principal[[#This Row],[nº períodos]]*tab_principal[[#This Row],[Qtde]] -> 0 | F18: Consumo | G18: Comum | H18: Custeio
A19: Software de sincronização de arquivos (Dropbox Plus) | B19: =10*aux!$C$20 -> 55 | C19: 18 | D19: 0 | E19: =tab_principal[[#This Row],[Valor Unitário]]*tab_principal[[#This Row],[nº períodos]]*tab_principal[[#This Row],[Qtde]] -> 0 | F19: Consumo | G19: Comum | H19: Custeio
A20: Software de versionamento (GitHub Pro Team) | B20: 22 | C20: 18 | D20: 0 | E20: =tab_principal[[#This Row],[Valor Unitário]]*tab_principal[[#This Row],[nº períodos]]*tab_principal[[#This Row],[Qtde]] -> 0 | F20: Consumo | G20: Comum | H20: Custeio
A21: Taxa Publicação Congresso ou Periódico | B21: 15000 | C21: 1 | D21: 0 | E21: =tab_principal[[#This Row],[Valor Unitário]]*tab_principal[[#This Row],[nº períodos]]*tab_principal[[#This Row],[Qtde]] -> 0 | F21: Consumo | G21: Comum | H21: Custeio
A22: Todoist Business | B22: 396 | C22: 2 | D22: 0 | E22: =tab_principal[[#This Row],[Valor Unitário]]*tab_principal[[#This Row],[nº períodos]]*tab_principal[[#This Row],[Qtde]] -> 0 | F22: Consumo | G22: Comum | H22: Custeio
A23: Bolsas de Pós-Doutorado | B23: 7200 | C23: 18 | D23: 1 | E23: =tab_principal[[#This Row],[Valor Unitário]]*tab_principal[[#This Row],[nº períodos]]*tab_principal[[#This Row],[Qtde]] -> 129600 | F23: Bolsa | G23: Comum | H23: Custeio
A24: Bolsas para Graduando | B24: 1100 | C24: 18 | D24: 2 | E24: =tab_principal[[#This Row],[Valor Unitário]]*tab_principal[[#This Row],[nº períodos]]*tab_principal[[#This Row],[Qtde]] -> 39600 | F24: Bolsa | G24: Comum | H24: Custeio
A25: Computador para Coordenador - H | B25: 18000 | C25: 1 | D25: 1 | E25: =tab_principal[[#This Row],[Valor Unitário]]*tab_principal[[#This Row],[nº períodos]]*tab_principal[[#This Row],[Qtde]] -> 18000 | F25: Permanente | G25: Henrique | H25: Capital
A26: Computadores para Alunos | B26: 15000 | C26: 1 | D26: 4 | E26: =tab_principal[[#This Row],[Valor Unitário]]*tab_principal[[#This Row],[nº períodos]]*tab_principal[[#This Row],[Qtde]] -> 60000 | F26: Permanente | G26: Comum | H26: Capital
A27: Diária Internacional - A | B27: 2035 | C27: 1 | D27: 0 | E27: =tab_principal[[#This Row],[Valor Unitário]]*tab_principal[[#This Row],[nº períodos]]*tab_principal[[#This Row],[Qtde]] -> 0 | F27: Diária | G27: Anselmo | H27: Custeio
A28: Diária Internacional - D | B28: 2035 | C28: 1 | D28: 0 | E28: =tab_principal[[#This Row],[Valor Unitário]]*tab_principal[[#This Row],[nº períodos]]*tab_principal[[#This Row],[Qtde]] -> 0 | F28: Diária | G28: Durigan | H28: Custeio
A29: Diária Internacional - R | B29: 2035 | C29: 1 | D29: 0 | E29: =tab_principal[[#This Row],[Valor Unitário]]*tab_principal[[#This Row],[nº períodos]]*tab_principal[[#This Row],[Qtde]] -> 0 | F29: Diária | G29: Roberto | H29: Custeio
A30: Diária Nacional - - Vinda Anselmo e aluno | B30: 350 | C30: 1 | D30: 14 | E30: =tab_principal[[#This Row],[Valor Unitário]]*tab_principal[[#This Row],[nº períodos]]*tab_principal[[#This Row],[Qtde]] -> 4900 | F30: Diária | G30: Comum | H30: Custeio
A31: Diária Nacional - Workshop | B31: 350 | C31: 1 | D31: 4 | E31: =tab_principal[[#This Row],[Valor Unitário]]*tab_principal[[#This Row],[nº períodos]]*tab_principal[[#This Row],[Qtde]] -> 1400 | F31: Diária | G31: Comum | H31: Custeio
... A37: Exoesqueleto | B37: 1000000 | C37: 1 | D37: 1 | E37: =tab_principal[[#This Row],[Valor Unitário]]*tab_principal[[#This Row],[nº períodos]]*tab_principal[[#This Row],[Qtde]] -> 1000000 | F37: Permanente | G37: Comum | H37: Capital
A38: FINATEC: despesas operacionais e administrativas para gestão do projeto | B38: =0.15*Consolidado!C3 -> 436800 | C38: 1 | D38: 1 | E38: =tab_principal[[#This Row],[Valor Unitário]]*tab_principal[[#This Row],[nº períodos]]*tab_principal[[#This Row],[Qtde]] -> 436800 | F38: Serviço | G38: Comum | H38: Custeio
A39: IMUs YEI PrioVR | B39: 17900 | C39: 1 | D39: 1 | E39: =tab_principal[[#This Row],[Valor Unitário]]*tab_principal[[#This Row],[nº períodos]]*tab_principal[[#This Row],[Qtde]] -> 17900 | F39: Permanente | G39: Comum | H39: Capital
A40: Manutenção preventiva/corretiva do parque de equipamentos | B40: 100000 | C40: 1 | D40: 1 | E40: =tab_principal[[#This Row],[Valor Unitário]]*tab_principal[[#This Row],[nº períodos]]*tab_principal[[#This Row],[Qtde]] -> 100000 | F40: Serviço | G40: Comum | H40: Custeio
A41: Material para prototipagem eletromecânico | B41: 0 | C41: 1 | D41: 1 | E41: =tab_principal[[#This Row],[Valor Unitário]]*tab_principal[[#This Row],[nº períodos]]*tab_principal[[#This Row],[Qtde]] -> 0 | F41: Consumo | G41: Anselmo | H41: Custeio
A42: Material para prototipagem eletromecânico | B42: 0 | C42: 1 | D42: 1 | E42: =tab_principal[[#This Row],[Valor Unitário]]*tab_principal[[#This Row],[nº períodos]]*tab_principal[[#This Row],[Qtde]] -> 0 | F42: Consumo | G42: Durigan | H42: Custeio
A43: Passagem internacional ida e votla - A | B43: 10000 | C43: 1 | D43: 0 | E43: =tab_principal[[#This Row],[Valor Unitário]]*tab_principal[[#This Row],[nº períodos]]*tab_principal[[#This Row],[Qtde]] -> 0 | F43: Passagem | G43: Anselmo | H43: Custeio
A44: Passagem internacional ida e votla - D | B44: 10000 | C44: 1 | D44: 0 | E44: =tab_principal[[#This Row],[Valor Unitário]]*tab_principal[[#This Row],[nº períodos]]*tab_principal[[#This Row],[Qtde]] -> 0 | F44: Passagem | G44: Durigan | H44: Custeio
A45: Computadores | B45: 13590.5 | C45: 1 | D45: 0 | E45: =tab_principal[[#This Row],[Valor Unitário]]*tab_principal[[#This Row],[nº períodos]]*tab_principal[[#This Row],[Qtde]] -> 0 | F45: Permanente | G45: Durigan | H45: Custeio
A46: Passagem internacional ida e votla - R | B46: 10000 | C46: 1 | D46: 0 | E46: =tab_principal[[#This Row],[Valor Unitário]]*tab_principal[[#This Row],[nº períodos]]*tab_principal[[#This Row],[Qtde]] -> 0 | F46: Passagem | G46: Roberto | H46: Custeio
A47: Bolsa para Doutorando - H | B47: 4000 | C47: 18 | D47: 0 | E47: =tab_principal[[#This Row],[Valor Unitário]]*tab_principal[[#This Row],[nº períodos]]*tab_principal[[#This Row],[Qtde]] -> 0 | F47: Bolsa | G47: Henrique | H47: Custeio
A48: Passagem nacional ida e volta - A | B48: 4000 | C48: 1 | D48: 0 | E48: =tab_principal[[#This Row],[Valor Unitário]]*tab_principal[[#This Row],[nº períodos]]*tab_principal[[#This Row],[Qtde]] -> 0 | F48: Passagem | G48: Anselmo | H48: Custeio
...

Sheet Consolidado
B1: Valores Finais do Orçamento | C1: Valor
B2: Orçamento Atual | C2: =SUM(tab_principal[Total]) -> 2912000
B3: Orçamento Permitido | C3: 2912000
B4: Falta Alocar | C4: =C3-C2 -> 0
B6: Orçamento Consolidado por Categoria | C6: Categoria | D6: R$
B7: Bolsas | C7: Bolsa | D7: =SUMIFS(tab_principal[Total],tab_principal[Categoria],Tabela5123[[#This Row],[Categoria]]) -> 990000
B8: Diárias | C8: Diária | D8: =SUMIFS(tab_principal[Total],tab_principal[Categoria],Tabela5123[[#This Row],[Categoria]]) -> 6300
B9: Passagens | C9: Passagem | D9: =SUMIFS(tab_principal[Total],tab_principal[Categoria],Tabela5123[[#This Row],[Categoria]]) -> 16000
B10: Material de Consumo | C10: Consumo | D10: =SUMIFS(tab_principal[Total],tab_principal[Categoria],Tabela5123[[#This Row],[Categoria]]) -> 100000
B11: Material Permanente e Equipamentos | C11: Permanente | D11: =SUMIFS(tab_principal[Total],tab_principal[Categoria],Tabela5123[[#This Row],[Categoria]]) -> 1262900
B12: Serviços de Terceiros | C12: Serviço | D12: =SUMIFS(tab_principal[Total],tab_principal[Categoria],Tabela5123[[#This Row],[Categoria]]) -> 536800
B13: Total | D13: =SUBTOTAL(109,Tabela5123[R$]) -> 2912000
B15: Tipo de Despesa | C15: Total (R$) | D15: Proporção
B16: Custeio | C16: =SUMIFS(tab_principal[Total],tab_principal[Tipo de Verba],Tabela10136[[#This Row],[Tipo de Despesa]]) -> 1649100 | D16: =Tabela10136[[#This Row],[Total (R$)]]/Tabela10136[[#Totals],[Total (R$)]] -> 0.56631181
B17: Capital | C17: =SUMIFS(tab_principal[Total],tab_principal[Tipo de Verba],Tabela10136[[#This Row],[Tipo de Despesa]]) -> 1262900 | D17: =Tabela10136[[#This Row],[Total (R$)]]/Tabela10136[[#Totals],[Total (R$)]] -> 0.43368819
B18: Total | C18: =SUBTOTAL(109,Tabela10136[Total (R$)]) -> 2912000 | D18: =SUBTOTAL(109,Tabela10136[Proporção]) -> 1
B20: Cálculo geral das cotas | C20: Valor
B21: Total utilizado da cota Comum | C21: =SUMIFS(tab_principal[Total],tab_principal[Cota de quem],"Comum") -> 2127200
B22: Total disponível para cotas | C22: =C3-C21 -> 784800
B23: Cota disponível por pessoa | C23: =C22/4 -> 196200
B25: Cotista | C25: Valor | D25: Falta Utilizar
B26: Roberto | C26: =SUMIFS(tab_principal[Total],tab_principal[Cota de quem],Tabela11[[#This Row],[Cotista]]) -> 196200 | D26: =$C$23-Tabela11[[#This Row],[Valor]] -> 0
B27: Henrique | C27: =SUMIFS(tab_principal[Total],tab_principal[Cota de quem],Tabela11[[#This Row],[Cotista]]) -> 196200 | D27: =$C$23-Tabela11[[#This Row],[Valor]] -> 0
B28: Durigan | C28: =SUMIFS(tab_principal[Total],tab_principal[Cota de quem],Tabela11[[#This Row],[Cotista]]) -> 196200 | D28: =$C$23-Tabela11[[#This Row],[Valor]] -> 0
B29: Anselmo | C29: =SUMIFS(tab_principal[Total],tab_principal[Cota de quem],Tabela11[[#This Row],[Cotista]]) -> 196200 | D29: =$C$23-Tabela11[[#This Row],[Valor]] -> 0
C30: =SUBTOTAL(109,Tabela11[Valor]) -> 784800 | D30: =SUBTOTAL(109,Tabela11[Falta Utilizar]) -> 0 | E30: Checksum | F30: =IF(Tabela11[[#Totals],[Valor]]+Tabela11[[#Totals],[Falta Utilizar]]=C22,"ok","algo errado") -> ok

Sheet Por Cota
A3: Rótulos de Linha | B3: Soma de Valor Unitário | C3: Soma de nº períodos | D3: Soma de Qtde | E3: Soma de Total
A4: Anselmo | B4: 40875.5 | C4: 42 | D4: 3 | E4: 196200
A5: Bolsa | B5: 10900 | C5: 36 | D5: 2 | E5: 196200
A6: Bolsa de Coordenação - A | B6: 6900 | C6: 18 | D6: 1 | E6: 124200
A7: Bolsa para Doutorando - A | B7: 4000 | C7: 18 | D7: 1 | E7: 72000
A8: Consumo | B8: 0 | C8: 1 | D8: 1 | E8: 0
A9: Material para prototipagem eletromecânico | B9: 0 | C9: 1 | D9: 1 | E9: 0
A10: Diária | B10: 2385 | C10: 2 | D10: 0 | E10: 0
A11: Diária Internacional - A | B11: 2035 | C11: 1 | D11: 0 | E11: 0
A12: Diária Nacional - A | B12: 350 | C12: 1 | D12: 0 | E12: 0
A13: Passagem | B13: 14000 | C13: 2 | D13: 0 | E13: 0
A14: Passagem internacional ida e votla - A | B14: 10000 | C14: 1 | D14: 0 | E14: 0
A15: Passagem nacional ida e volta - A | B15: 4000 | C15: 1 | D15: 0 | E15: 0
... A93: Total Geral | B93: 2147014.5 | C93: 333 | D93: 53 | E93: 2912000

Sheet Por Categoria
A3: Rótulos de Linha | B3: Soma de Valor Unitário | C3: Soma de nº períodos | D3: Soma de Qtde | E3: Soma de Total
A4: Bolsa | B4: 61500 | C4: 252 | D4: 13 | E4: 990000
A5: Bolsa de Coordenação - A | B5: 6900 | C5: 18 | D5: 1 | E5: 124200
A6: Bolsa de Coordenação - D | B6: 6900 | C6: 18 | D6: 1 | E6: 124200
A7: Bolsa de Coordenação - H | B7: 6900 | C7: 18 | D7: 1 | E7: 124200
A8: Bolsa de Coordenação - R | B8: 6900 | C8: 18 | D8: 1 | E8: 124200
A9: Bolsa para Doutorando - A | B9: 4000 | C9: 18 | D9: 1 | E9: 72000
A10: Bolsa para Doutorando - D | B10: 4000 | C10: 18 | D10: 1 | E10: 72000
A11: Bolsa para Doutorando - H | B11: 4000 | C11: 18 | D11: 0 | E11: 0
A12: Bolsa para Doutorando - R | B12: 4000 | C12: 18 | D12: 1 | E12: 72000
A13: Bolsas de Graduação | B13: 1500 | C13: 18 | D13: 2 | E13: 54000
A14: Bolsas de Mestrado | B14: 3000 | C14: 18 | D14: 0 | E14: 0
A15: Bolsas de Mestrado - H | B15: 3000 | C15: 18 | D15: 1 | E15: 54000
... A65: Total Geral | B65: 2147014.5 | C65: 333 | D65: 53 | E65: 2912000

Sheet contrapartida
E1: 0.15 | F1: 18
C2: Especificação | D2: Sal./mês (R$) | E2: 6h/sem (R$) | F2: 18 meses(R$)
B3: João | C3: Professor adjunto em dedicação exclusiva | D3: 15983.49 | E3: =D3*$E$1 -> 2397.5235 | F3: =E3*$F$1 -> 43155.423
B4: Henrique | C4: Professor associado em dedicação exclusiva | D4: 23185.69 | E4: =D4*$E$1 -> 3477.8535 | F4: =E4*$F$1 -> 62601.363
B5: Roberto | C5: Professor adjunto em dedicação exclusiva | D5: 17075.02 | E5: =D5*$E$1 -> 2561.253 | F5: =E5*$F$1 -> 46102.554
B6: Maurício | C6: Professor adjunto em dedicação exclusiva | D6: 13052.04 | E6: =D6*$E$1 -> 1957.806 | F6: =E6*$F$1 -> 35240.508
C7: Total | F7: =SUBTOTAL(109,Tabela9[18 meses(R$)]) -> 187099.85

Sheet Whishlist
B1: Item | C1: Site Fabricante | D1: Valor USD | E1: Valor BRL | F1: Custos Extra | G1: Estimativa Total | H1: Condições
B2: Exoesqueleto - Atalante X | C2: https://en.wandercraft.eu/atalante-x-rehabilitation-exoskeleton | D2: 246000 | E2: =D2*5.5 -> 1353000 | F2: =E2*(0.25) -> 338250 | G2: =E2+F2 -> 1691250 | H2: FCA + 1 year Maintenance
B3: Exoesqueleto - NX A13 | C3: https://www.nxrehab.com/ | D3: 90000 | E3: =D3*5.5 -> 495000 | F3: =E3*(0.25) -> 123750 | G3: =E3+F3 -> 618750 | H3: Ex Works - Instalação e Treinamento
B4: Exoesqueleto - ExoMotus M4 | C4: https://www.fftai.com/products-exomotus-m4 | D4: quote | F4: =E4*(0.25) -> 0 | G4: =E4+F4 -> 0
B5: IMU Mocap - Xsense | C5: https://www.movella.com/products/motion-capture | D5: quote | F5: =E5*(0.25) -> 0 | G5: =E5+F5 -> 0 | H5: Sensores não muito caro, mas software sim, Anselmo não recomenda
B6: IMU Mocap - Yost Labs PrioVR | C6: https://yostlabs.com/priovr/ | D6: quote | F6: =E6*(0.25) -> 0 | G6: =E6+F6 -> 0
B7: Mocap Chines - dica Luis | D7: quote | F7: =E7*(0.25) -> 0 | G7: =E7+F7 -> 0
B8: FES - Stim2Go | C8: https://pajunk.com/us/products/pain-management/fes-nmes-tens/ | E8: 40000 | F8: =E8*(0.25) -> 10000 | G8: =E8+F8 -> 50000
B9: FES - manutenção Hasomed P4 | D9: quote
B10: FES Cycling - Fesia Bike | C10: https://fesiatechnology.com/en/fesia-bike/ | D10: quote
B11: FES Cycling - Myolin | C11: https://myolyn.com/for-home/overview/
B12: FES Cycling - RT300 | C12: https://restorative-therapies.com/rt300/
B15: Material de Consumo. Assinaturas
B16: Item | C16: Valor unitário | D16: Meses/Anos | E16: Qtde | F16: Total
B17: Github Team | C17: 22 | D17: 18 | E17: 6 | F17: =Tabela617302[[#This Row],[Meses/Anos]]*Tabela617302[[#This Row],[Valor unitário]]*Tabela617302[[#This Row],[Qtde]] -> 2376
B18: Claude Pro | C18: 92 | D18: 18 | E18: 0 | F18: =Tabela617302[[#This Row],[Meses/Anos]]*Tabela617302[[#This Row],[Valor unitário]]*Tabela617302[[#This Row],[Qtde]] -> 0
B19: Google AI Pro | C19: 96.99 | D19: 18 | E19: 0 | F19: =Tabela617302[[#This Row],[Meses/Anos]]*Tabela617302[[#This Row],[Valor unitário]]*Tabela617302[[#This Row],[Qtde]] -> 0
B20: Todoist Business | C20: 396 | D20: 2 | E20: 0 | F20: =Tabela617302[[#This Row],[Meses/Anos]]*Tabela617302[[#This Row],[Valor unitário]]*Tabela617302[[#This Row],[Qtde]] -> 0
B21: Adobe Acrobat Pro | C21: 997.5 | D21: 2 | E21: 0 | F21: =Tabela617302[[#This Row],[Meses/Anos]]*Tabela617302[[#This Row],[Valor unitário]]*Tabela617302[[#This Row],[Qtde]] -> 0
B22: Class Point | C22: 1152 | D22: 2 | E22: 0 | F22: =Tabela617302[[#This Row],[Meses/Anos]]*Tabela617302[[#This Row],[Valor unitário]]*Tabela617302[[#This Row],[Qtde]] -> 0
B23: Gamma | C23: 840 | D23: 2 | E23: 0 | F23: =Tabela617302[[#This Row],[Meses/Anos]]*Tabela617302[[#This Row],[Valor unitário]]*Tabela617302[[#This Row],[Qtde]] -> 0
B24: Elicit | C24: 66 | D24: 18 | E24: 0 | F24: =Tabela617302[[#This Row],[Meses/Anos]]*Tabela617302[[#This Row],[Valor unitário]]*Tabela617302[[#This Row],[Qtde]] -> 0
B25: Jenni | C25: 610 | D25: 2 | E25: 0 | F25: =Tabela617302[[#This Row],[Meses/Anos]]*Tabela617302[[#This Row],[Valor unitário]]*Tabela617302[[#This Row],[Qtde]] -> 0
B26: Reserach Rabbit | C26: 55 | D26: 18 | E26: 0 | F26: =Tabela617302[[#This Row],[Meses/Anos]]*Tabela617302[[#This Row],[Valor unitário]]*Tabela617302[[#This Row],[Qtde]] -> 0
B27: Consensus | C27: 660 | D27: 2 | E27: 0 | F27: =Tabela617302[[#This Row],[Meses/Anos]]*Tabela617302[[#This Row],[Valor unitário]]*Tabela617302[[#This Row],[Qtde]] -> 0
B28: Perplexity | C28: 110 | D28: 18 | E28: 0 | F28: =Tabela617302[[#This Row],[Meses/Anos]]*Tabela617302[[#This Row],[Valor unitário]]*Tabela617302[[#This Row],[Qtde]] -> 0
B29: Grammarly | C29: =12*#REF!*12 -> #REF! | D29: 2 | E29: 0 | F29: =Tabela617302[[#This Row],[Meses/Anos]]*Tabela617302[[#This Row],[Valor unitário]]*Tabela617302[[#This Row],[Qtde]] -> #REF!
B30: Dropbox Pro | E30: 6 | F30: =Tabela617302[[#This Row],[Meses/Anos]]*Tabela617302[[#This Row],[Valor unitário]]*Tabela617302[[#This Row],[Qtde]] -> 0
F31: =Tabela617302[[#This Row],[Meses/Anos]]*Tabela617302[[#This Row],[Valor unitário]]*Tabela617302[[#This Row],[Qtde]] -> 0
F32: =Tabela617302[[#This Row],[Meses/Anos]]*Tabela617302[[#This Row],[Valor unitário]]*Tabela617302[[#This Row],[Qtde]] -> 0
F33: =Tabela617302[[#This Row],[Meses/Anos]]*Tabela617302[[#This Row],[Valor unitário]]*Tabela617302[[#This Row],[Qtde]] -> 0
F34: =Tabela617302[[#This Row],[Meses/Anos]]*Tabela617302[[#This Row],[Valor unitário]]*Tabela617302[[#This Row],[Qtde]] -> 0
F35: =Tabela617302[[#This Row],[Meses/Anos]]*Tabela617302[[#This Row],[Valor unitário]]*Tabela617302[[#This Row],[Qtde]] -> 0
F36: =Tabela617302[[#This Row],[Meses/Anos]]*Tabela617302[[#This Row],[Valor unitário]]*Tabela617302[[#This Row],[Qtde]] -> 0
F37: =Tabela617302[[#This Row],[Meses/Anos]]*Tabela617302[[#This Row],[Valor unitário]]*Tabela617302[[#This Row],[Qtde]] -> 0
F38: =Tabela617302[[#This Row],[Meses/Anos]]*Tabela617302[[#This Row],[Valor unitário]]*Tabela617302[[#This Row],[Qtde]] -> 0
B39: Total | F39: =SUBTOTAL(109,Tabela617302[Total]) -> #REF!
B41: Material de Consumo
B42: Item | C42: Valor unitário | D42: Qtde | E42: Total
B43: Prototipagem Smart Walker | C43: 100000 | D43: 1 | E43: =Tabela6244[[#This Row],[Valor unitário]]*Tabela6244[[#This Row],[Qtde]] -> 100000
...

Sheet aux
B2: Categorias | C2: Tipo da Cota | D2: Cota de quem | E2: Tipo de Verba
B3: Consumo | C3: Comum | D3: Comum | E3: Custeio
B4: Permanente | C4: Individual | D4: Roberto | E4: Capital
B5: Bolsa | D5: Henrique
B6: Diária | D6: Durigan
B7: Passagem | D7: Anselmo
B8: Serviço | D8: A Designar
B11: Valor de cada Bolsa | C11: Valor no projeto
B12: Pós-Doutor | C12: 7200
B13: Doutorado | C13: 6900
B14: Doutorando | C14: 4000
B15: Mestrado | C15: 3000
B16: Mestrando | C16: 2100
B17: Graduado | C17: 1500
B18: Graduando | C18: 1100
B20: USD/BRL | C20: 5.5
